Workbook

Sheet MUEBLES
A1: Cantidad | B1: ID Módulo | C1: Mueble | D1: Precio Unit. Blanco | E1: Precio Unit. Maderado
B2: ALA-RIN-656832 | C2: Alacena Rinconera 650 x 680 x 320 mm | D2: 2692.08 | E2: 3321.8658
B3: ALA-1PU-306832 | C3: Alacena 1 Puerta 300 x 680 x 320 mm | D3: 1609.2284 | E3: 2016.3004
B4: ALA-1PU-406832 | C4: Alacena 1 Puerta 400 x 680 x 320 mm | D4: 1855.1811 | E4: 2319.5009
B5: ALA-1PU-506832 | C5: Alacena 1 Puerta 500 x 680 x 320 mm | D5: 2106.0299 | E5: 2613.6642
B6: ALA-1PU-606832 | C6: Alacena 1 Puerta 600 x 680 x 320 mm | D6: 2356.8786 | E6: 2907.8275
B7: ALA-2PU-706832 | C7: Alacena 2 Puertas 700 x 680 x 320 mm | D7: 2932.4086 | E7: 3462.672
B8: ALA-2PU-806832 | C8: Alacena 2 Puertas 800 x 680 x 320 mm | D8: 3183.2573 | E8: 3756.8353
B9: ALA-2PU-906832 | C9: Alacena 2 Puertas 900 x 680 x 320 mm | D9: 3432.8975 | E9: 4049.7901
B10: ALA-BAS-503432 | C10: Alacena Basculante 500 x 340 x 320 mm | D10: ='📊 Resumen y Cotización'!E21 -> 2603.8228 | E10: ='📊 Resumen y Cotización'!H21 -> 3390.6832
B11: ALA-BAS-603432 | C11: Alacena Basculante 600 x 340 x 320 mm | D11: 1623.7291 | E11: 2015.9109
B12: ALA-BAS-703432 | C12: Alacena Basculante 700 x 340 x 320 mm | D12: 1771.5051 | E12: 2190.544
B13: ALA-BAS-803432 | C13: Alacena Basculante 800 x 340 x 320 mm | D13: 1919.281 | E13: 2365.1771
B14: ALA-NIC-276832 | C14: Alacena Nicho Abierto 270 x 680 x 320 mm | D14: 1332.2447 | E14: 1496.2447
B15: ALA-MIC-503432 | C15: Alacena Nicho Microondas 500 x 340 x 320 mm | D15: ='📊 Resumen y Cotización'!E26 -> 2121.3042 | E15: ='📊 Resumen y Cotización'!H26 -> 2389.3042
B16: ALA-MIC-603432 | C16: Alacena Nicho Microondas 600 x 340 x 320 mm | D16: 1231.2649 | E16: 1395.2649
B17: GAB-RIN-1057258 | C17: Gabinete Rinconero 1050 x 720 x 580 mm | D17: 4504.9847 | E17: 5557.6467
B18: GAB-1PU-307258 | C18: Gabinete 1 Puerta 300 x 720 x 580 mm | D18: 2417.6515 | E18: 2991.311
B19: GAB-1PU-407258 | C19: Gabinete 1 Puerta 400 x 720 x 580 mm | D19: 2712.0903 | E19: 3338.7819
B20: GAB-1PU-507258 | C20: Gabinete 1 Puerta 500 x 720 x 580 mm | D20: 3006.5291 | E20: 3686.2528
B21: GAB-1PU-607258 | C21: Gabinete 1 Puerta 600 x 720 x 580 mm | D21: 3302.8639 | E21: 4036.2517
B22: GAB-2PU-707258 | C22: Gabinete 2 Puertas 700 x 720 x 580 mm | D22: 3931.0708 | E22: 4655.7147
B23: GAB-2PU-807258 | C23: Gabinete 2 Puertas 800 x 720 x 580 mm | D23: 4232.7096 | E23: 5012.7856
B24: GAB-2PU-907258 | C24: Gabinete 2 Puertas 900 x 720 x 580 mm | D24: 4534.3484 | E24: 5369.8565
B25: GAB-3CA-407258 | C25: Gabinete 3 Cajones 400 x 720 x 580 mm | D25: 5346.4467 | E25: 6269.8763
B26: GAB-3CA-507258 | C26: Gabinete 3 Cajones 500 x 720 x 580 mm | D26: 5818.4021 | E26: 6840.7689
B27: GAB-3CA-607258 | C27: Gabinete 3 Cajones 600 x 720 x 580 mm | D27: 6290.3575 | E27: 7411.6615
B28: GAB-MIC-603658 | C28: Gabinete Nicho Microondas 600 x 360 x 580 mm | D28: ='📊 Resumen y Cotización'!E39 -> 3448.9284 | E28: ='📊 Resumen y Cotización'!H39 -> 3716.9284
B29: GAB-1CA-603658 | C29: Gabinete 1 Cajon 600 x 360 x 580 mm | D29: ='📊 Resumen y Cotización'!E40 -> 5590.5653 | E29: ='📊 Resumen y Cotización'!H40 -> 7212.7094
B30: GAB-NIC-207258 | C30: Gabinete Nicho 200 x 720 x 580 mm | D30: 2105.7105 | E30: 2162.6226
B31: GAB-NIC-TOA-207258 | C31: Gabinete Nicho Toallero 200 x 720 x 580 mm | D31: 2436.5499 | E31: 2526.8539
B32: TAR-1PU-607258 | C32: Gabinete Tarja 1 Puerta 600 x 720 x 580 mm | D32: 2798.3182 | E32: 3336.1712
B33: TAR-2PU-707258 | C33: Gabinete Tarja 2 Puertas 700 x 720 x 580 mm | D33: 3344.5709 | E33: 3852.6721
B34: TAR-2PU-807258 | C34: Gabinete Tarja 2 Puertas 800 x 720 x 580 mm | D34: 3563.3248 | E34: 4105.8502
B35: TAR-2PU-907258 | C35: Gabinete Tarja 2 Puertas 900 x 720 x 580 mm | D35: 3782.0787 | E35: 4359.0283
B36: DES-1PU-4021058 | C36: Despensa 1 Puerta 400 x 2100 x 580 mm | D36: 6853.0481 | E36: 8113.7517
B37: DES-1PU-6021058 | C37: Despensa 1 Puerta 600 x 2100 x 580 mm | D37: 8387.3513 | E37: 9913.1631
B38: DES-2PU-8021058 | C38: Despensa 2 Puertas 800 x 2100 x 580 mm | D38: 10223.553 | E38: 12020.521
B39: DES-HOR-6021058 | C39: Torre Horno y Micro 600 x 2100 x 580 mm | D39: 8788.1361 | E39: 9053.4828
B40: DES-HOR-7021058 | C40: Torre Horno y Micro 700 x 2100 x 580 mm | D40: 10202.726 | E40: 10312.439
...

Sheet 📊 Resumen y Cotización
A1: RESUMEN Y COTIZACIÓN COMPARATIVA
A2: Compara el mismo proyecto en muebles interiores blancos y totalmente maderados; los precios pendientes quedan bloqueados.
A3: Proyecto: | B3: Mobiliario Completo (Exportado desde SketchUp) | H3: Fecha: | I3: 46221 | K3: Moneda: | L3: MXN ($)
A4: Cliente: | B4: Público General / Cotización Proyecto
A6: CANTIDAD TOTAL | C6: MUEBLES BLANCO | E6: MUEBLES MADERADO | G6: CUBIERTA | I6: FINAL BLANCO | K6: FINAL MADERADO | M6: DIFERENCIA
A7: =SUM(A13:A60) -> 9 | C7: =L25 -> 47739.652 | E7: =M25 -> 59954.276 | G7: ='🧱 Cubiertas'!H4 -> 0 | I7: =L28 -> 55377.996 | K7: =M28 -> 69546.96 | M7: =IF(ISNUMBER(M28),M28-L28,"PENDIENTE") -> 14168.964
A8: Unidades cotizadas | C8: Venta de muebles | E8: Venta conocida | G8: Partida separada del mobiliario | I8: Muebles + cubierta + IVA | K8: Se habilita sin alertas | M8: Maderado − blanco
A10: COTIZADOR COMPARATIVO DE MUEBLES | K10: ESTRUCTURA DE VENTA
A11: Edita Cantidad y los campos amarillos. BLA y MAD se recalculan en paralelo; Estado MAD advierte módulos con costos incompletos. | K11: =IF(SUM('📋 Explosión y Despiece Bla'!$V$2:$V$643)+SUM('📋 Explosión y Despiece Mad'!$V$2:$V$713)=0,"✓ COSTOS COMPLETOS","⚠ REVISAR PRECIOS FALTANTES") -> ✓ COSTOS COMPLETOS
A12: Cantidad | B12: ID Módulo | C12: Mueble | D12: Costo BLA | E12: Precio BLA | F12: Total BLA | G12: Costo MAD | H12: Precio MAD | I12: Total MAD | J12: Estado MAD | K12: Concepto | L12: Blanco | M12: Maderado | N12: Nota
A13: 1 | B13: ALA-RIN-656832 | C13: Alacena Rinconera 650 x 680 x 320 mm | D13: =SUMIF('📋 Explosión y Despiece Bla'!$K$2:$K$643,B13,'📋 Explosión y Despiece Bla'!$S$2:$S$643) -> 703.90877 | E13: =D13*$L$14+$L$15 -> 4716.1888 | F13: =A13*E13 -> 4716.1888 | G13: =SUMIF('📋 Explosión y Despiece Mad'!$K$2:$K$713,B13,'📋 Explosión y Despiece Mad'!$S$2:$S$713) -> 922.07751 | H13: =G13*$L$14+$L$15 -> 6177.9193 | I13: =A13*H13 -> 6177.9193 | J13: =IF(SUMIF('📋 Explosión y Despiece Mad'!$K$2:$K$713,B13,'📋 Explosión y Despiece Mad'!$V$2:$V$713)>0,"PENDIENTE","OK") -> OK | K13: Costo directo | L13: =A13*D13+A14*D14+A15*D15+A16*D16+A17*D17+A18*D18+A19*D19+A20*D20+A22*D22+A23*D23+A24*D24+A25*D25+A27*D27+A28*D28+A29*D29+A30*D30+A31*D31+A32*D32+A33*D33+A34*D34+A35*D35+A36*D36+A37*D37+A38*D38+A41*D41+A42*D42+A43*D43+A44*D44+A45*D45+A46*D46+A47*D47+A48*D48+A49*D49+A50*D50+A51*D51+A54*D54+A55*D55+A56*D56+A57*D57+A58*D58+A60*D60 -> 7125.3211 | M13: =A13*G13+A14*G14+A15*G15+A16*G16+A17*G17+A18*G18+A19*G19+A20*G20+A22*G22+A23*G23+A24*G24+A25*G25+A27*G27+A28*G28+A29*G29+A30*G30+A31*G31+A32*G32+A33*G33+A34*G34+A35*G35+A36*G36+A37*G37+A38*G38+A41*G41+A42*G42+A43*G43+A44*G44+A45*G45+A46*G46+A47*G47+A48*G48+A49*G49+A50*G50+A51*G51+A54*G54+A55*G55+A56*G56+A57*G57+A58*G58+A60*G60 -> 8948.3994 | N13: Antes de margen y mano de obra
A14: 0 | B14: ALA-1PU-306832 | C14: Alacena 1 Puerta 300 x 680 x 320 mm | D14: =SUMIF('📋 Explosión y Despiece Bla'!$K$2:$K$643,B14,'📋 Explosión y Despiece Bla'!$S$2:$S$643) -> 423.39961 | E14: =D14*$L$14+$L$15 -> 2836.7774 | F14: =A14*E14 -> 0 | G14: =SUMIF('📋 Explosión y Despiece Mad'!$K$2:$K$713,B14,'📋 Explosión y Despiece Mad'!$S$2:$S$713) -> 558.55436 | H14: =G14*$L$14+$L$15 -> 3742.3142 | I14: =A14*H14 -> 0 | J14: =IF(SUMIF('📋 Explosión y Despiece Mad'!$K$2:$K$713,B14,'📋 Explosión y Despiece Mad'!$V$2:$V$713)>0,"PENDIENTE","OK") -> OK | K14: Factor de venta | L14: 6.7 | M14: =L14 -> 6.7 | N14: Común para ambos acabados
A15: 0 | B15: ALA-1PU-406832 | C15: Alacena 1 Puerta 400 x 680 x 320 mm | D15: =SUMIF('📋 Explosión y Despiece Bla'!$K$2:$K$643,B15,'📋 Explosión y Despiece Bla'!$S$2:$S$643) -> 487.26541 | E15: =D15*$L$14+$L$15 -> 3264.6783 | F15: =A15*E15 -> 0 | G15: =SUMIF('📋 Explosión y Despiece Mad'!$K$2:$K$713,B15,'📋 Explosión y Despiece Mad'!$S$2:$S$713) -> 642.51766 | H15: =G15*$L$14+$L$15 -> 4304.8683 | I15: =A15*H15 -> 0 | J15: =IF(SUMIF('📋 Explosión y Despiece Mad'!$K$2:$K$713,B15,'📋 Explosión y Despiece Mad'!$V$2:$V$713)>0,"PENDIENTE","OK") -> OK | K15: Mano de obra / unidad | L15: 0 | M15: =L15 -> 0 | N15: Común para ambos acabados
A16: 0 | B16: ALA-1PU-506832 | C16: Alacena 1 Puerta 500 x 680 x 320 mm | D16: =SUMIF('📋 Explosión y Despiece Bla'!$K$2:$K$643,B16,'📋 Explosión y Despiece Bla'!$S$2:$S$643) -> 552.35521 | E16: =D16*$L$14+$L$15 -> 3700.7799 | F16: =A16*E16 -> 0 | G16: =SUMIF('📋 Explosión y Despiece Mad'!$K$2:$K$713,B16,'📋 Explosión y Despiece Mad'!$S$2:$S$713) -> 724.07748 | H16: =G16*$L$14+$L$15 -> 4851.3191 | I16: =A16*H16 -> 0 | J16: =IF(SUMIF('📋 Explosión y Despiece Mad'!$K$2:$K$713,B16,'📋 Explosión y Despiece Mad'!$V$2:$V$713)>0,"PENDIENTE","OK") -> OK | K16: Venta de muebles | L16: =SUM(F13:F60) -> 47739.652 | M16: =SUM(I13:I60) -> 59954.276 | N16: Excluye cubiertas
A17: 0 | B17: ALA-1PU-606832 | C17: Alacena 1 Puerta 600 x 680 x 320 mm | D17: =SUMIF('📋 Explosión y Despiece Bla'!$K$2:$K$643,B17,'📋 Explosión y Despiece Bla'!$S$2:$S$643) -> 617.445 | E17: =D17*$L$14+$L$15 -> 4136.8815 | F17: =A17*E17 -> 0 | G17: =SUMIF('📋 Explosión y Despiece Mad'!$K$2:$K$713,B17,'📋 Explosión y Despiece Mad'!$S$2:$S$713) -> 805.6373 | H17: =G17*$L$14+$L$15 -> 5397.7699 | I17: =A17*H17 -> 0 | J17: =IF(SUMIF('📋 Explosión y Despiece Mad'!$K$2:$K$713,B17,'📋 Explosión y Despiece Mad'!$V$2:$V$713)>0,"PENDIENTE","OK") -> OK
A18: 0 | B18: ALA-2PU-706832 | C18: Alacena 2 Puertas 700 x 680 x 320 mm | D18: =SUMIF('📋 Explosión y Despiece Bla'!$K$2:$K$643,B18,'📋 Explosión y Despiece Bla'!$S$2:$S$643) -> 773.66478 | E18: =D18*$L$14+$L$15 -> 5183.554 | F18: =A18*E18 -> 0 | G18: =SUMIF('📋 Explosión y Despiece Mad'!$K$2:$K$713,B18,'📋 Explosión y Despiece Mad'!$S$2:$S$713) -> 954.32709 | H18: =G18*$L$14+$L$15 -> 6393.9915 | I18: =A18*H18 -> 0 | J18: =IF(SUMIF('📋 Explosión y Despiece Mad'!$K$2:$K$713,B18,'📋 Explosión y Despiece Mad'!$V$2:$V$713)>0,"PENDIENTE","OK") -> OK | K18: CUBIERTA SEPARADA
A19: 2 | B19: ALA-2PU-806832 | C19: Alacena 2 Puertas 800 x 680 x 320 mm | D19: =SUMIF('📋 Explosión y Despiece Bla'!$K$2:$K$643,B19,'📋 Explosión y Despiece Bla'!$S$2:$S$643) -> 838.75457 | E19: =D19*$L$14+$L$15 -> 5619.6556 | F19: =A19*E19 -> 11239.311 | G19: =SUMIF('📋 Explosión y Despiece Mad'!$K$2:$K$713,B19,'📋 Explosión y Despiece Mad'!$S$2:$S$713) -> 1035.8869 | H19: =G19*$L$14+$L$15 -> 6940.4423 | I19: =A19*H19 -> 13880.885 | J19: =IF(SUMIF('📋 Explosión y Despiece Mad'!$K$2:$K$713,B19,'📋 Explosión y Despiece Mad'!$V$2:$V$713)>0,"PENDIENTE","OK") -> OK | K19: Tipo de cubierta | L19: SIN CUBIERTA | M19: =L19 -> SIN CUBIERTA | N19: Seleccionar aquí para toda la cotización
A20: 0 | B20: ALA-2PU-906832 | C20: Alacena 2 Puertas 900 x 680 x 320 mm | D20: =SUMIF('📋 Explosión y Despiece Bla'!$K$2:$K$643,B20,'📋 Explosión y Despiece Bla'!$S$2:$S$643) -> 903.5088 | E20: =D20*$L$14+$L$15 -> 6053.509 | F20: =A20*E20 -> 0 | G20: =SUMIF('📋 Explosión y Despiece Mad'!$K$2:$K$713,B20,'📋 Explosión y Despiece Mad'!$S$2:$S$713) -> 1117.1112 | H20: =G20*$L$14+$L$15 -> 7484.6447 | I20: =A20*H20 -> 0 | J20: =IF(SUMIF('📋 Explosión y Despiece Mad'!$K$2:$K$713,B20,'📋 Explosión y Despiece Mad'!$V$2:$V$713)>0,"PENDIENTE","OK") -> OK | K20: Multiplicador | L20: ='🧱 Cubiertas'!E3 -> 4 | M20: =L20 -> 4 | N20: Mismo concepto que el factor de muebles
A21: 0 | B21: ALA-BAS-503432 | C21: Alacena Basculante 500 x 340 x 320 mm | D21: =SUMIF('📋 Explosión y Despiece Bla'!$K$2:$K$643,B21,'📋 Explosión y Despiece Bla'!$S$2:$S$643) -> 388.63027 | E21: =D21*$L$14+$L$15 -> 2603.8228 | F21: =A21*E21 -> 0 | G21: =SUMIF('📋 Explosión y Despiece Mad'!$K$2:$K$713,B21,'📋 Explosión y Despiece Mad'!$S$2:$S$713) -> 506.07213 | H21: =G21*$L$14+$L$15 -> 3390.6832 | I21: =A21*H21 -> 0 | J21: =IF(SUMIF('📋 Explosión y Despiece Mad'!$K$2:$K$713,B21,'📋 Explosión y Despiece Mad'!$V$2:$V$713)>0,"PENDIENTE","OK") -> OK | K21: Costo cubierta | L21: ='🧱 Cubiertas'!H5 -> 0 | M21: =L21 -> 0 | N21: Costo según largo total redondeado a múltiplos de 1.20 m
A22: 1 | B22: ALA-BAS-603432 | C22: Alacena Basculante 600 x 340 x 320 mm | D22: =SUMIF('📋 Explosión y Despiece Bla'!$K$2:$K$643,B22,'📋 Explosión y Despiece Bla'!$S$2:$S$643) -> 426.90847 | E22: =D22*$L$14+$L$15 -> 2860.2867 | F22: =A22*E22 -> 2860.2867 | G22: =SUMIF('📋 Explosión y Despiece Mad'!$K$2:$K$713,B22,'📋 Explosión y Despiece Mad'!$S$2:$S$713) -> 554.57695 | H22: =G22*$L$14+$L$15 -> 3715.6656 | I22: =A22*H22 -> 3715.6656 | J22: =IF(SUMIF('📋 Explosión y Despiece Mad'!$K$2:$K$713,B22,'📋 Explosión y Despiece Mad'!$V$2:$V$713)>0,"PENDIENTE","OK") -> OK | K22: Venta cubierta | L22: ='🧱 Cubiertas'!H4 -> 0 | M22: =L22 -> 0 | N22: Partida independiente; no incluida en precios unitarios de muebles
A23: 1 | B23: ALA-BAS-703432 | C23: Alacena Basculante 700 x 340 x 320 mm | D23: =SUMIF('📋 Explosión y Despiece Bla'!$K$2:$K$643,B23,'📋 Explosión y Despiece Bla'!$S$2:$S$643) -> 465.18666 | E23: =D23*$L$14+$L$15 -> 3116.7506 | F23: =A23*E23 -> 3116.7506 | G23: =SUMIF('📋 Explosión y Despiece Mad'!$K$2:$K$713,B23,'📋 Explosión y Despiece Mad'!$S$2:$S$713) -> 603.08178 | H23: =G23*$L$14+$L$15 -> 4040.6479 | I23: =A23*H23 -> 4040.6479 | J23: =IF(SUMIF('📋 Explosión y Despiece Mad'!$K$2:$K$713,B23,'📋 Explosión y Despiece Mad'!$V$2:$V$713)>0,"PENDIENTE","OK") -> OK
A24: 0 | B24: ALA-BAS-803432 | C24: Alacena Basculante 800 x 340 x 320 mm | D24: =SUMIF('📋 Explosión y Despiece Bla'!$K$2:$K$643,B24,'📋 Explosión y Despiece Bla'!$S$2:$S$643) -> 503.46485 | E24: =D24*$L$14+$L$15 -> 3373.2145 | F24: =A24*E24 -> 0 | G24: =SUMIF('📋 Explosión y Despiece Mad'!$K$2:$K$713,B24,'📋 Explosión y Despiece Mad'!$S$2:$S$713) -> 651.5866 | H24: =G24*$L$14+$L$15 -> 4365.6303 | I24: =A24*H24 -> 0 | J24: =IF(SUMIF('📋 Explosión y Despiece Mad'!$K$2:$K$713,B24,'📋 Explosión y Despiece Mad'!$V$2:$V$713)>0,"PENDIENTE","OK") -> OK | K24: PRESUPUESTO TOTAL
A25: 1 | B25: ALA-NIC-276832 | C25: Alacena Nicho Abierto 270 x 680 x 320 mm | D25: =SUMIF('📋 Explosión y Despiece Bla'!$K$2:$K$643,B25,'📋 Explosión y Despiece Bla'!$S$2:$S$643) -> 379.54202 | E25: =D25*$L$14+$L$15 -> 2542.9315 | F25: =A25*E25 -> 2542.9315 | G25: =SUMIF('📋 Explosión y Despiece Mad'!$K$2:$K$713,B25,'📋 Explosión y Despiece Mad'!$S$2:$S$713) -> 419.54202 | H25: =G25*$L$14+$L$15 -> 2810.9315 | I25: =A25*H25 -> 2810.9315 | J25: =IF(SUMIF('📋 Explosión y Despiece Mad'!$K$2:$K$713,B25,'📋 Explosión y Despiece Mad'!$V$2:$V$713)>0,"PENDIENTE","OK") -> OK | K25: Muebles | L25: =L16 -> 47739.652 | M25: =M16 -> 59954.276 | N25: Solo mobiliario; excluye cubierta
A26: 0 | B26: ALA-MIC-503432 | C26: Alacena Nicho Microondas 500 x 340 x 320 mm | D26: =SUMIF('📋 Explosión y Despiece Bla'!$K$2:$K$643,B26,'📋 Explosión y Despiece Bla'!$S$2:$S$643) -> 316.61257 | E26: =D26*$L$14+$L$15 -> 2121.3042 | F26: =A26*E26 -> 0 | G26: =SUMIF('📋 Explosión y Despiece Mad'!$K$2:$K$713,B26,'📋 Explosión y Despiece Mad'!$S$2:$S$713) -> 356.61257 | H26: =G26*$L$14+$L$15 -> 2389.3042 | I26: =A26*H26 -> 0 | J26: =IF(SUMIF('📋 Explosión y Despiece Mad'!$K$2:$K$713,B26,'📋 Explosión y Despiece Mad'!$V$2:$V$713)>0,"PENDIENTE","OK") -> OK | K26: Cubierta | L26: ='🧱 Cubiertas'!H4 -> 0 | M26: ='🧱 Cubiertas'!H4 -> 0 | N26: Cobro separado por largo total de cocina
A27: 0 | B27: ALA-MIC-603432 | C27: Alacena Nicho Microondas 600 x 340 x 320 mm | D27: =SUMIF('📋 Explosión y Despiece Bla'!$K$2:$K$643,B27,'📋 Explosión y Despiece Bla'!$S$2:$S$643) -> 351.5288 | E27: =D27*$L$14+$L$15 -> 2355.2429 | F27: =A27*E27 -> 0 | G27: =SUMIF('📋 Explosión y Despiece Mad'!$K$2:$K$713,B27,'📋 Explosión y Despiece Mad'!$S$2:$S$713) -> 391.5288 | H27: =G27*$L$14+$L$15 -> 2623.2429 | I27: =A27*H27 -> 0 | J27: =IF(SUMIF('📋 Explosión y Despiece Mad'!$K$2:$K$713,B27,'📋 Explosión y Despiece Mad'!$V$2:$V$713)>0,"PENDIENTE","OK") -> OK | K27: IVA (16%) | L27: =SUM(L25:L26)*16% -> 7638.3442 | M27: =SUM(M25:M26)*16% -> 9592.6841 | N27: 16% sobre muebles y cubierta
A28: 1 | B28: GAB-RIN-1057258 | C28: Gabinete Rinconero 1050 x 720 x 580 mm | D28: =SUMIF('📋 Explosión y Despiece Bla'!$K$2:$K$643,B28,'📋 Explosión y Despiece Bla'!$S$2:$S$643) -> 1161.3762 | E28: =D28*$L$14+$L$15 -> 7781.2205 | F28: =A28*E28 -> 7781.2205 | G28: =SUMIF('📋 Explosión y Despiece Mad'!$K$2:$K$713,B28,'📋 Explosión y Despiece Mad'!$S$2:$S$713) -> 1540.2864 | H28: =G28*$L$14+$L$15 -> 10319.919 | I28: =A28*H28 -> 10319.919 | J28: =IF(SUMIF('📋 Explosión y Despiece Mad'!$K$2:$K$713,B28,'📋 Explosión y Despiece Mad'!$V$2:$V$713)>0,"PENDIENTE","OK") -> OK | K28: GRAN TOTAL | L28: =SUM(L25:L27) -> 55377.996 | M28: =IF(SUM('📋 Explosión y Despiece Mad'!$V$2:$V$713)>0,"PENDIENTE",SUM(M25:M27)) -> 69546.96 | N28: Suma de muebles, cubierta e IVA
A29: 0 | B29: GAB-1PU-307258 | C29: Gabinete 1 Puerta 300 x 720 x 580 mm | D29: =SUMIF('📋 Explosión y Despiece Bla'!$K$2:$K$643,B29,'📋 Explosión y Despiece Bla'!$S$2:$S$643) -> 625.98997 | E29: =D29*$L$14+$L$15 -> 4194.1328 | F29: =A29*E29 -> 0 | G29: =SUMIF('📋 Explosión y Despiece Mad'!$K$2:$K$713,B29,'📋 Explosión y Despiece Mad'!$S$2:$S$713) -> 823.42706 | H29: =G29*$L$14+$L$15 -> 5516.9613 | I29: =A29*H29 -> 0 | J29: =IF(SUMIF('📋 Explosión y Despiece Mad'!$K$2:$K$713,B29,'📋 Explosión y Despiece Mad'!$V$2:$V$713)>0,"PENDIENTE","OK") -> OK | K29: Diferencia MAD vs BLA | M29: =IF(ISNUMBER(M28),M28-L28,"PENDIENTE") -> 14168.964 | N29: Disponible con costos completos
A30: 0 | B30: GAB-1PU-407258 | C30: Gabinete 1 Puerta 400 x 720 x 580 mm | D30: =SUMIF('📋 Explosión y Despiece Bla'!$K$2:$K$643,B30,'📋 Explosión y Despiece Bla'!$S$2:$S$643) -> 702.10003 | E30: =D30*$L$14+$L$15 -> 4704.0702 | F30: =A30*E30 -> 0 | G30: =SUMIF('📋 Explosión y Despiece Mad'!$K$2:$K$713,B30,'📋 Explosión y Despiece Mad'!$S$2:$S$713) -> 919.52979 | H30: =G30*$L$14+$L$15 -> 6160.8496 | I30: =A30*H30 -> 0 | J30: =IF(SUMIF('📋 Explosión y Despiece Mad'!$K$2:$K$713,B30,'📋 Explosión y Despiece Mad'!$V$2:$V$713)>0,"PENDIENTE","OK") -> OK
A31: 0 | B31: GAB-1PU-507258 | C31: Gabinete 1 Puerta 500 x 720 x 580 mm | D31: =SUMIF('📋 Explosión y Despiece Bla'!$K$2:$K$643,B31,'📋 Explosión y Despiece Bla'!$S$2:$S$643) -> 778.21009 | E31: =D31*$L$14+$L$15 -> 5214.0076 | F31: =A31*E31 -> 0 | G31: =SUMIF('📋 Explosión y Despiece Mad'!$K$2:$K$713,B31,'📋 Explosión y Despiece Mad'!$S$2:$S$713) -> 1015.6325 | H31: =G31*$L$14+$L$15 -> 6804.7378 | I31: =A31*H31 -> 0 | J31: =IF(SUMIF('📋 Explosión y Despiece Mad'!$K$2:$K$713,B31,'📋 Explosión y Despiece Mad'!$V$2:$V$713)>0,"PENDIENTE","OK") -> OK | K31: PRESUPUESTO TOTAL DISTRIBUIDOR
A32: 0 | B32: GAB-1PU-607258 | C32: Gabinete 1 Puerta 600 x 720 x 580 mm | D32: =SUMIF('📋 Explosión y Despiece Bla'!$K$2:$K$643,B32,'📋 Explosión y Despiece Bla'!$S$2:$S$643) -> 854.79416 | E32: =D32*$L$14+$L$15 -> 5727.1208 | F32: =A32*E32 -> 0 | G32: =SUMIF('📋 Explosión y Despiece Mad'!$K$2:$K$713,B32,'📋 Explosión y Despiece Mad'!$S$2:$S$713) -> 1112.4857 | H32: =G32*$L$14+$L$15 -> 7453.6545 | I32: =A32*H32 -> 0 | J32: =IF(SUMIF('📋 Explosión y Despiece Mad'!$K$2:$K$713,B32,'📋 Explosión y Despiece Mad'!$V$2:$V$713)>0,"PENDIENTE","OK") -> OK | K32: Muebles | L32: =L25*65% -> 31030.773 | M32: =IF(ISNUMBER(M25),M25*65%,"PENDIENTE") -> 38970.279 | N32: 35% de descuento sobre muebles
A33: 0 | B33: GAB-2PU-707258 | C33: Gabinete 2 Puertas 700 x 720 x 580 mm | D33: =SUMIF('📋 Explosión y Despiece Bla'!$K$2:$K$643,B33,'📋 Explosión y Despiece Bla'!$S$2:$S$643) -> 1024.4223 | E33: =D33*$L$14+$L$15 -> 6863.6291 | F33: =A33*E33 -> 0 | G33: =SUMIF('📋 Explosión y Despiece Mad'!$K$2:$K$713,B33,'📋 Explosión y Despiece Mad'!$S$2:$S$713) -> 1279.0795 | H33: =G33*$L$14+$L$15 -> 8569.8327 | I33: =A33*H33 -> 0 | J33: =IF(SUMIF('📋 Explosión y Despiece Mad'!$K$2:$K$713,B33,'📋 Explosión y Despiece Mad'!$V$2:$V$713)>0,"PENDIENTE","OK") -> OK | K33: Cubierta | L33: =L26*65% -> 0 | M33: =IF(ISNUMBER(M26),M26*65%,"PENDIENTE") -> 0 | N33: 35% de descuento sobre cubierta
A34: 0 | B34: GAB-2PU-807258 | C34: Gabinete 2 Puertas 800 x 720 x 580 mm | D34: =SUMIF('📋 Explosión y Despiece Bla'!$K$2:$K$643,B34,'📋 Explosión y Despiece Bla'!$S$2:$S$643) -> 1102.3323 | E34: =D34*$L$14+$L$15 -> 7385.6265 | F34: =A34*E34 -> 0 | G34: =SUMIF('📋 Explosión y Despiece Mad'!$K$2:$K$713,B34,'📋 Explosión y Despiece Mad'!$S$2:$S$713) -> 1378.0322 | H34: =G34*$L$14+$L$15 -> 9232.816 | I34: =A34*H34 -> 0 | J34: =IF(SUMIF('📋 Explosión y Despiece Mad'!$K$2:$K$713,B34,'📋 Explosión y Despiece Mad'!$V$2:$V$713)>0,"PENDIENTE","OK") -> OK | K34: IVA (16%) | L34: =SUM(L32:L33)*16% -> 4964.9238 | M34: =IF(OR(NOT(ISNUMBER(M32)),NOT(ISNUMBER(M33))),"PENDIENTE",SUM(M32:M33)*16%) -> 6235.2447 | N34: 16% sobre muebles y cubierta con descuento
A35: 0 | B35: GAB-2PU-907258 | C35: Gabinete 2 Puertas 900 x 720 x 580 mm | D35: =SUMIF('📋 Explosión y Despiece Bla'!$K$2:$K$643,B35,'📋 Explosión y Despiece Bla'!$S$2:$S$643) -> 1180.2424 | E35: =D35*$L$14+$L$15 -> 7907.6239 | F35: =A35*E35 -> 0 | G35: =SUMIF('📋 Explosión y Despiece Mad'!$K$2:$K$713,B35,'📋 Explosión y Despiece Mad'!$S$2:$S$713) -> 1476.985 | H35: =G35*$L$14+$L$15 -> 9895.7992 | I35: =A35*H35 -> 0 | J35: =IF(SUMIF('📋 Explosión y Despiece Mad'!$K$2:$K$713,B35,'📋 Explosión y Despiece Mad'!$V$2:$V$713)>0,"PENDIENTE","OK") -> OK | K35: GRAN TOTAL DISTRIBUIDOR | L35: =SUM(L32:L34) -> 35995.697 | M35: =IF(OR(NOT(ISNUMBER(M32)),NOT(ISNUMBER(M33)),NOT(ISNUMBER(M34))),"PENDIENTE",SUM(M32:M34)) -> 45205.524 | N35: Total distribuidor con IVA
A36: 1 | B36: GAB-3CA-407258 | C36: Gabinete 3 Cajones 400 x 720 x 580 mm | D36: =SUMIF('📋 Explosión y Despiece Bla'!$K$2:$K$643,B36,'📋 Explosión y Despiece Bla'!$S$2:$S$643) -> 1375.9038 | E36: =D36*$L$14+$L$15 -> 9218.5552 | F36: =A36*E36 -> 9218.5552 | G36: =SUMIF('📋 Explosión y Despiece Mad'!$K$2:$K$713,B36,'📋 Explosión y Despiece Mad'!$S$2:$S$713) -> 1705.4619 | H36: =G36*$L$14+$L$15 -> 11426.595 | I36: =A36*H36 -> 11426.595 | J36: =IF(SUMIF('📋 Explosión y Despiece Mad'!$K$2:$K$713,B36,'📋 Explosión y Despiece Mad'!$V$2:$V$713)>0,"PENDIENTE","OK") -> OK | K36: Diferencia MAD vs BLA | M36: =IF(AND(ISNUMBER(L35),ISNUMBER(M35)),M35-L35,"PENDIENTE") -> 9209.8267 | N36: Disponible con costos completos
A37: 0 | B37: GAB-3CA-507258 | C37: Gabinete 3 Cajones 500 x 720 x 580 mm | D37: =SUMIF('📋 Explosión y Despiece Bla'!$K$2:$K$643,B37,'📋 Explosión y Despiece Bla'!$S$2:$S$643) -> 1496.9653 | E37: =D37*$L$14+$L$15 -> 10029.668 | F37: =A37*E37 -> 0 | G37: =SUMIF('📋 Explosión y Despiece Mad'!$K$2:$K$713,B37,'📋 Explosión y Despiece Mad'!$S$2:$S$713) -> 1864.4679 | H37: =G37*$L$14+$L$15 -> 12491.935 | I37: =A37*H37 -> 0 | J37: =IF(SUMIF('📋 Explosión y Despiece Mad'!$K$2:$K$713,B37,'📋 Explosión y Despiece Mad'!$V$2:$V$713)>0,"PENDIENTE","OK") -> OK
A38: 0 | B38: GAB-3CA-607258 | C38: Gabinete 3 Cajones 600 x 720 x 580 mm | D38: =SUMIF('📋 Explosión y Despiece Bla'!$K$2:$K$643,B38,'📋 Explosión y Despiece Bla'!$S$2:$S$643) -> 1618.0269 | E38: =D38*$L$14+$L$15 -> 10840.781 | F38: =A38*E38 -> 0 | G38: =SUMIF('📋 Explosión y Despiece Mad'!$K$2:$K$713,B38,'📋 Explosión y Despiece Mad'!$S$2:$S$713) -> 2023.4738 | H38: =G38*$L$14+$L$15 -> 13557.275 | I38: =A38*H38 -> 0 | J38: =IF(SUMIF('📋 Explosión y Despiece Mad'!$K$2:$K$713,B38,'📋 Explosión y Despiece Mad'!$V$2:$V$713)>0,"PENDIENTE","OK") -> OK
A39: 0 | B39: GAB-MIC-603658 | C39: Gabinete Nicho Microondas 600 x 360 x 580 mm | D39: =SUMIF('📋 Explosión y Despiece Bla'!$K$2:$K$643,B39,'📋 Explosión y Despiece Bla'!$S$2:$S$643) -> 514.76544 | E39: =D39*$L$14+$L$15 -> 3448.9284 | F39: =A39*E39 -> 0 | G39: =SUMIF('📋 Explosión y Despiece Mad'!$K$2:$K$713,B39,'📋 Explosión y Despiece Mad'!$S$2:$S$713) -> 554.76544 | H39: =G39*$L$14+$L$15 -> 3716.9284 | I39: =A39*H39 -> 0 | J39: =IF(SUMIF('📋 Explosión y Despiece Mad'!$K$2:$K$713,B39,'📋 Explosión y Despiece Mad'!$V$2:$V$713)>0,"PENDIENTE","OK") -> OK
A40: 0 | B40: GAB-1CA-603658 | C40: Gabinete 1 Cajon 600 x 360 x 580 mm | D40: =SUMIF('📋 Explosión y Despiece Bla'!$K$2:$K$643,B40,'📋 Explosión y Despiece Bla'!$S$2:$S$643) -> 834.41273 | E40: =D40*$L$14+$L$15 -> 5590.5653 | F40: =A40*E40 -> 0 | G40: =SUMIF('📋 Explosión y Despiece Mad'!$K$2:$K$713,B40,'📋 Explosión y Despiece Mad'!$S$2:$S$713) -> 1076.5238 | H40: =G40*$L$14+$L$15 -> 7212.7094 | I40: =A40*H40 -> 0 | J40: =IF(SUMIF('📋 Explosión y Despiece Mad'!$K$2:$K$713,B40,'📋 Explosión y Despiece Mad'!$V$2:$V$713)>0,"PENDIENTE","OK") -> OK
A41: 0 | B41: GAB-NIC-207258 | C41: Gabinete Nicho 200 x 720 x 580 mm | D41: =SUMIF('📋 Explosión y Despiece Bla'!$K$2:$K$643,B41,'📋 Explosión y Despiece Bla'!$S$2:$S$643) -> 598.91581 | E41: =D41*$L$14+$L$15 -> 4012.736 | F41: =A41*E41 -> 0 | G41: =SUMIF('📋 Explosión y Despiece Mad'!$K$2:$K$713,B41,'📋 Explosión y Despiece Mad'!$S$2:$S$713) -> 599.94325 | H41: =G41*$L$14+$L$15 -> 4019.6198 | I41: =A41*H41 -> 0 | J41: =IF(SUMIF('📋 Explosión y Despiece Mad'!$K$2:$K$713,B41,'📋 Explosión y Despiece Mad'!$V$2:$V$713)>0,"PENDIENTE","OK") -> OK
A42: 0 | B42: GAB-NIC-TOA-207258 | C42: Gabinete Nicho Toallero 200 x 720 x 580 mm | D42: =SUMIF('📋 Explosión y Despiece Bla'!$K$2:$K$643,B42,'📋 Explosión y Despiece Bla'!$S$2:$S$643) -> 676.91574 | E42: =D42*$L$14+$L$15 -> 4535.3355 | F42: =A42*E42 -> 0 | G42: =SUMIF('📋 Explosión y Despiece Mad'!$K$2:$K$713,B42,'📋 Explosión y Despiece Mad'!$S$2:$S$713) -> 687.72474 | H42: =G42*$L$14+$L$15 -> 4607.7558 | I42: =A42*H42 -> 0 | J42: =IF(SUMIF('📋 Explosión y Despiece Mad'!$K$2:$K$713,B42,'📋 Explosión y Despiece Mad'!$V$2:$V$713)>0,"PENDIENTE","OK") -> OK
...

Sheet 🧱 Cubiertas
A1: COTIZADOR DE CUBIERTAS POR MÓDULO
A2: Calcula cubiertas para gabinetes bajos y tarjas; el largo total seleccionado se cobra en múltiplos de 1.20 m × 0.60 m.
A3: Tipo de cubierta | B3: ='📊 Resumen y Cotización'!L19 -> SIN CUBIERTA | D3: Multiplicador | E3: 4 | G3: Módulos aplicables | H3: =COUNTIF(C7:C54,"SÍ") -> 19
A4: Costo por ML | B4: =IFERROR(_xlfn.XLOOKUP(B3,'⚙️ Configuración Costos'!$A$23:$A$25,'⚙️ Configuración Costos'!$B$23:$B$25),0) -> 0 | D4: Largo real seleccionado | E4: {=SUMPRODUCT('📊 Resumen y Cotización'!$A$13:$A$60,$D$7:$D$54,--($C$7:$C$54="SÍ"))} -> 2.25 | G4: Venta seleccionada | H4: =SUMPRODUCT('📊 Resumen y Cotización'!$A$13:$A$60,$F$7:$F$54) -> 0
A5: Estado | B5: =IF(B3="SIN CUBIERTA","○ SIN CUBIERTA",IF(B4>0,"✓ PRECIO CONFIGURADO","⚠ REVISAR CONFIGURACIÓN")) -> ○ SIN CUBIERTA | D5: Largo cobrable | E5: =IF(E4=0,0,ROUNDUP(E4/1.2,0)*1.2) -> 2.4 | G5: Costo seleccionado | H5: =SUMPRODUCT('📊 Resumen y Cotización'!$A$13:$A$60,$E$7:$E$54) -> 0
A6: ID Módulo | B6: Mueble | C6: Aplica | D6: Ancho (m) | E6: Costo cubierta | F6: Precio cubierta
A7: ='📊 Resumen y Cotización'!B13 -> ALA-RIN-656832 | B7: ='📊 Resumen y Cotización'!C13 -> Alacena Rinconera 650 x 680 x 320 mm | C7: =IF(OR(LEFT(A7,4)="GAB-",LEFT(A7,4)="TAR-"),"SÍ","NO") -> NO | D7: 0 | E7: =IF(AND(C7="SÍ",$B$3<>"SIN CUBIERTA",$E$4>0),D7*$B$4*($E$5/$E$4),0) -> 0 | F7: =E7*$E$3 -> 0
A8: ='📊 Resumen y Cotización'!B14 -> ALA-1PU-306832 | B8: ='📊 Resumen y Cotización'!C14 -> Alacena 1 Puerta 300 x 680 x 320 mm | C8: =IF(OR(LEFT(A8,4)="GAB-",LEFT(A8,4)="TAR-"),"SÍ","NO") -> NO | D8: 0 | E8: =IF(AND(C8="SÍ",$B$3<>"SIN CUBIERTA",$E$4>0),D8*$B$4*($E$5/$E$4),0) -> 0 | F8: =E8*$E$3 -> 0
A9: ='📊 Resumen y Cotización'!B15 -> ALA-1PU-406832 | B9: ='📊 Resumen y Cotización'!C15 -> Alacena 1 Puerta 400 x 680 x 320 mm | C9: =IF(OR(LEFT(A9,4)="GAB-",LEFT(A9,4)="TAR-"),"SÍ","NO") -> NO | D9: 0 | E9: =IF(AND(C9="SÍ",$B$3<>"SIN CUBIERTA",$E$4>0),D9*$B$4*($E$5/$E$4),0) -> 0 | F9: =E9*$E$3 -> 0
A10: ='📊 Resumen y Cotización'!B16 -> ALA-1PU-506832 | B10: ='📊 Resumen y Cotización'!C16 -> Alacena 1 Puerta 500 x 680 x 320 mm | C10: =IF(OR(LEFT(A10,4)="GAB-",LEFT(A10,4)="TAR-"),"SÍ","NO") -> NO | D10: 0 | E10: =IF(AND(C10="SÍ",$B$3<>"SIN CUBIERTA",$E$4>0),D10*$B$4*($E$5/$E$4),0) -> 0 | F10: =E10*$E$3 -> 0
A11: ='📊 Resumen y Cotización'!B17 -> ALA-1PU-606832 | B11: ='📊 Resumen y Cotización'!C17 -> Alacena 1 Puerta 600 x 680 x 320 mm | C11: =IF(OR(LEFT(A11,4)="GAB-",LEFT(A11,4)="TAR-"),"SÍ","NO") -> NO | D11: 0 | E11: =IF(AND(C11="SÍ",$B$3<>"SIN CUBIERTA",$E$4>0),D11*$B$4*($E$5/$E$4),0) -> 0 | F11: =E11*$E$3 -> 0
A12: ='📊 Resumen y Cotización'!B18 -> ALA-2PU-706832 | B12: ='📊 Resumen y Cotización'!C18 -> Alacena 2 Puertas 700 x 680 x 320 mm | C12: =IF(OR(LEFT(A12,4)="GAB-",LEFT(A12,4)="TAR-"),"SÍ","NO") -> NO | D12: 0 | E12: =IF(AND(C12="SÍ",$B$3<>"SIN CUBIERTA",$E$4>0),D12*$B$4*($E$5/$E$4),0) -> 0 | F12: =E12*$E$3 -> 0
A13: ='📊 Resumen y Cotización'!B19 -> ALA-2PU-806832 | B13: ='📊 Resumen y Cotización'!C19 -> Alacena 2 Puertas 800 x 680 x 320 mm | C13: =IF(OR(LEFT(A13,4)="GAB-",LEFT(A13,4)="TAR-"),"SÍ","NO") -> NO | D13: 0 | E13: =IF(AND(C13="SÍ",$B$3<>"SIN CUBIERTA",$E$4>0),D13*$B$4*($E$5/$E$4),0) -> 0 | F13: =E13*$E$3 -> 0
A14: ='📊 Resumen y Cotización'!B20 -> ALA-2PU-906832 | B14: ='📊 Resumen y Cotización'!C20 -> Alacena 2 Puertas 900 x 680 x 320 mm | C14: =IF(OR(LEFT(A14,4)="GAB-",LEFT(A14,4)="TAR-"),"SÍ","NO") -> NO | D14: 0 | E14: =IF(AND(C14="SÍ",$B$3<>"SIN CUBIERTA",$E$4>0),D14*$B$4*($E$5/$E$4),0) -> 0 | F14: =E14*$E$3 -> 0
A15: ='📊 Resumen y Cotización'!B21 -> ALA-BAS-503432 | B15: ='📊 Resumen y Cotización'!C21 -> Alacena Basculante 500 x 340 x 320 mm | C15: =IF(OR(LEFT(A15,4)="GAB-",LEFT(A15,4)="TAR-"),"SÍ","NO") -> NO | D15: 0 | E15: =IF(AND(C15="SÍ",$B$3<>"SIN CUBIERTA",$E$4>0),D15*$B$4*($E$5/$E$4),0) -> 0 | F15: =E15*$E$3 -> 0
A16: ='📊 Resumen y Cotización'!B22 -> ALA-BAS-603432 | B16: ='📊 Resumen y Cotización'!C22 -> Alacena Basculante 600 x 340 x 320 mm | C16: =IF(OR(LEFT(A16,4)="GAB-",LEFT(A16,4)="TAR-"),"SÍ","NO") -> NO | D16: 0 | E16: =IF(AND(C16="SÍ",$B$3<>"SIN CUBIERTA",$E$4>0),D16*$B$4*($E$5/$E$4),0) -> 0 | F16: =E16*$E$3 -> 0
A17: ='📊 Resumen y Cotización'!B23 -> ALA-BAS-703432 | B17: ='📊 Resumen y Cotización'!C23 -> Alacena Basculante 700 x 340 x 320 mm | C17: =IF(OR(LEFT(A17,4)="GAB-",LEFT(A17,4)="TAR-"),"SÍ","NO") -> NO | D17: 0 | E17: =IF(AND(C17="SÍ",$B$3<>"SIN CUBIERTA",$E$4>0),D17*$B$4*($E$5/$E$4),0) -> 0 | F17: =E17*$E$3 -> 0
A18: ='📊 Resumen y Cotización'!B24 -> ALA-BAS-803432 | B18: ='📊 Resumen y Cotización'!C24 -> Alacena Basculante 800 x 340 x 320 mm | C18: =IF(OR(LEFT(A18,4)="GAB-",LEFT(A18,4)="TAR-"),"SÍ","NO") -> NO | D18: 0 | E18: =IF(AND(C18="SÍ",$B$3<>"SIN CUBIERTA",$E$4>0),D18*$B$4*($E$5/$E$4),0) -> 0 | F18: =E18*$E$3 -> 0
... A45: ='📊 Resumen y Cotización'!B51 -> DES-HOR-7021058 | B45: ='📊 Resumen y Cotización'!C51 -> Torre Horno y Micro 700 x 2100 x 580 mm | C45: =IF(OR(LEFT(A45,4)="GAB-",LEFT(A45,4)="TAR-"),"SÍ","NO") -> NO | D45: 0 | E45: =IF(AND(C45="SÍ",$B$3<>"SIN CUBIERTA",$E$4>0),D45*$B$4*($E$5/$E$4),0) -> 0 | F45: =E45*$E$3 -> 0
A46: DES-HOR-3CA-6021058 | B46: Torre Horno y Micro c/Cajones 600 x 2100 x 580 mm | C46: NO | D46: 0 | E46: =IF(C46="SÍ",D46*$B$4,0) -> 0 | F46: =E46*$E$3 -> 0
A47: DES-HOR-3CA-7021058 | B47: Torre Horno y Micro c/Cajones 700 x 2100 x 580 mm | C47: NO | D47: 0 | E47: =IF(C47="SÍ",D47*$B$4,0) -> 0 | F47: =E47*$E$3 -> 0
A48: ='📊 Resumen y Cotización'!B54 -> DES-NIC-4021061 | B48: ='📊 Resumen y Cotización'!C54 -> Despensa Nicho 400 x 2100 x 610 mm | C48: =IF(OR(LEFT(A48,4)="GAB-",LEFT(A48,4)="TAR-"),"SÍ","NO") -> NO | D48: 0 | E48: =IF(AND(C48="SÍ",$B$3<>"SIN CUBIERTA",$E$4>0),D48*$B$4*($E$5/$E$4),0) -> 0 | F48: =E48*$E$3 -> 0
A49: ='📊 Resumen y Cotización'!B55 -> PAN-ALA-3434 | B49: ='📊 Resumen y Cotización'!C55 -> Panel Alacena 340 x 340 mm | C49: =IF(OR(LEFT(A49,4)="GAB-",LEFT(A49,4)="TAR-"),"SÍ","NO") -> NO | D49: 0 | E49: =IF(AND(C49="SÍ",$B$3<>"SIN CUBIERTA",$E$4>0),D49*$B$4*($E$5/$E$4),0) -> 0 | F49: =E49*$E$3 -> 0
A50: ='📊 Resumen y Cotización'!B56 -> PAN-ALA-6834 | B50: ='📊 Resumen y Cotización'!C56 -> Panel Alacena 680 x 340 mm | C50: =IF(OR(LEFT(A50,4)="GAB-",LEFT(A50,4)="TAR-"),"SÍ","NO") -> NO | D50: 0 | E50: =IF(AND(C50="SÍ",$B$3<>"SIN CUBIERTA",$E$4>0),D50*$B$4*($E$5/$E$4),0) -> 0 | F50: =E50*$E$3 -> 0
A51: ='📊 Resumen y Cotización'!B57 -> PAN-GAB-7261 | B51: ='📊 Resumen y Cotización'!C57 -> Panel Gabinete 720 x 610 mm | C51: =IF(OR(LEFT(A51,4)="GAB-",LEFT(A51,4)="TAR-"),"SÍ","NO") -> NO | D51: 0 | E51: =IF(AND(C51="SÍ",$B$3<>"SIN CUBIERTA",$E$4>0),D51*$B$4*($E$5/$E$4),0) -> 0 | F51: =E51*$E$3 -> 0
A52: ='📊 Resumen y Cotización'!B58 -> PAN-DES-21061 | B52: ='📊 Resumen y Cotización'!C58 -> Panel Despensa 2100 x 610 mm | C52: =IF(OR(LEFT(A52,4)="GAB-",LEFT(A52,4)="TAR-"),"SÍ","NO") -> NO | D52: 0 | E52: =IF(AND(C52="SÍ",$B$3<>"SIN CUBIERTA",$E$4>0),D52*$B$4*($E$5/$E$4),0) -> 0 | F52: =E52*$E$3 -> 0
A53: PAN-DES-21034 | B53: Panel Despensa 2100 x 340 mm | C53: NO | D53: 0 | E53: =IF(C53="SÍ",D53*$B$4,0) -> 0 | F53: =E53*$E$3 -> 0
A54: ='📊 Resumen y Cotización'!B60 -> ZOC-24015 | B54: ='📊 Resumen y Cotización'!C60 -> Zoclo 2400 x 150 mm | C54: =IF(OR(LEFT(A54,4)="GAB-",LEFT(A54,4)="TAR-"),"SÍ","NO") -> NO | D54: 0 | E54: =IF(AND(C54="SÍ",$B$3<>"SIN CUBIERTA",$E$4>0),D54*$B$4*($E$5/$E$4),0) -> 0 | F54: =E54*$E$3 -> 0

Sheet 📋 Explosión y Despiece Bla
A1: Cantidad | B1: Largo (mm) | C1: Ancho (mm) | D1: Descripción de la Pieza / Módulo | E1: Materia Prima | F1: Veta | G1: Largo 1 | H1: Largo 2 | I1: Ancho 1 | J1: Ancho 2 | K1: Codigo | L1: Código Pieza | M1: M² Totales | N1: ML Cintilla | O1: Costo Unit. Mat/Herr | P1: Costo Tot. Mat/Herr | Q1: Costo Unit. Cintilla | R1: Costo Tot. Cintilla | S1: Costo Total Elemento | T1: Validación | U1: Detalle de alerta | V1: Alerta
A2: Alacena Rinconera 650 x 680 x 320 mm
A3: 1 | B3: 680 | C3: 320 | D3: Lateral Derecho | E3: ARAUCO BLANCO | F3: 0 | G3: 1 | H3: 1 | I3: 1 | J3: 1 | K3: ALA-RIN-656832 | L3: LAT-ALA-6832-D | M3: =IF(AND(ISNUMBER(B3),ISNUMBER(C3),B3>0,C3>0),A3*(B3*C3/1000000),0) -> 0.2176 | N3: =IF(AND(ISNUMBER(B3),B3>0),A3*(((G3+H3)*B3+(I3+J3)*C3)/1000),0) -> 2 | O3: =IF(E3="HERRAJE",IFERROR(_xlfn.XLOOKUP(D3,'⚙️ Configuración Costos'!$A$11:$A$20,'⚙️ Configuración Costos'!$B$11:$B$20),""),IFERROR(_xlfn.XLOOKUP(E3,'⚙️ Configuración Costos'!$A$5:$A$6,'⚙️ Configuración Costos'!$B$5:$B$6),"")) -> 239.84262 | P3: =IF(E3="HERRAJE",A3*O3,M3*O3) -> 52.189755 | Q3: =IF(E3="HERRAJE",0,IFERROR(_xlfn.XLOOKUP(E3,'⚙️ Configuración Costos'!$E$5:$E$6,'⚙️ Configuración Costos'!$F$5:$F$6),"")) -> 6 | R3: =N3*Q3 -> 12 | S3: =P3+R3 -> 64.189755 | T3: =IF(K3="","SIN ID MÓDULO",IF(E3="HERRAJE",IF(OR(O3="",O3<=0),"SIN PRECIO HERRAJE","OK"),IF(OR(O3="",O3<=0),"SIN PRECIO MATERIAL",IF(AND(N3>0,OR(Q3="",Q3<=0)),"SIN PRECIO CINTILLA","OK")))) -> OK | U3: =IF(T3="OK","",IF(T3="SIN PRECIO HERRAJE","Capturar precio: "&D3,IF(T3="SIN PRECIO MATERIAL","Configurar material: "&E3,IF(T3="SIN PRECIO CINTILLA","Configurar cintilla: "&E3,IF(T3="SIN ID MÓDULO","Revisar ID del módulo",""))))) | V3: =IF(T3="OK",0,IF(T3="",0,1)) -> 0
A4: 1 | B4: 680 | C4: 320 | D4: Lateral Izquierdo | E4: ARAUCO BLANCO | F4: 0 | G4: 1 | H4: 1 | I4: 1 | J4: 1 | K4: ALA-RIN-656832 | L4: LAT-ALA-6832-I | M4: =IF(AND(ISNUMBER(B4),ISNUMBER(C4),B4>0,C4>0),A4*(B4*C4/1000000),0) -> 0.2176 | N4: =IF(AND(ISNUMBER(B4),B4>0),A4*(((G4+H4)*B4+(I4+J4)*C4)/1000),0) -> 2 | O4: =IF(E4="HERRAJE",IFERROR(_xlfn.XLOOKUP(D4,'⚙️ Configuración Costos'!$A$11:$A$20,'⚙️ Configuración Costos'!$B$11:$B$20),""),IFERROR(_xlfn.XLOOKUP(E4,'⚙️ Configuración Costos'!$A$5:$A$6,'⚙️ Configuración Costos'!$B$5:$B$6),"")) -> 239.84262 | P4: =IF(E4="HERRAJE",A4*O4,M4*O4) -> 52.189755 | Q4: =IF(E4="HERRAJE",0,IFERROR(_xlfn.XLOOKUP(E4,'⚙️ Configuración Costos'!$E$5:$E$6,'⚙️ Configuración Costos'!$F$5:$F$6),"")) -> 6 | R4: =N4*Q4 -> 12 | S4: =P4+R4 -> 64.189755 | T4: =IF(K4="","SIN ID MÓDULO",IF(E4="HERRAJE",IF(OR(O4="",O4<=0),"SIN PRECIO HERRAJE","OK"),IF(OR(O4="",O4<=0),"SIN PRECIO MATERIAL",IF(AND(N4>0,OR(Q4="",Q4<=0)),"SIN PRECIO CINTILLA","OK")))) -> OK | U4: =IF(T4="OK","",IF(T4="SIN PRECIO HERRAJE","Capturar precio: "&D4,IF(T4="SIN PRECIO MATERIAL","Configurar material: "&E4,IF(T4="SIN PRECIO CINTILLA","Configurar cintilla: "&E4,IF(T4="SIN ID MÓDULO","Revisar ID del módulo",""))))) | V4: =IF(T4="OK",0,IF(T4="",0,1)) -> 0
A5: 1 | B5: 649 | C5: 619 | D5: Respaldo Alacena | E5: ARAUCO BLANCO | F5: 0 | G5: 0 | H5: 0 | I5: 0 | J5: 0 | K5: ALA-RIN-656832 | L5: RES-ALA-6865 | M5: =IF(AND(ISNUMBER(B5),ISNUMBER(C5),B5>0,C5>0),A5*(B5*C5/1000000),0) -> 0.401731 | N5: =IF(AND(ISNUMBER(B5),B5>0),A5*(((G5+H5)*B5+(I5+J5)*C5)/1000),0) -> 0 | O5: =IF(E5="HERRAJE",IFERROR(_xlfn.XLOOKUP(D5,'⚙️ Configuración Costos'!$A$11:$A$20,'⚙️ Configuración Costos'!$B$11:$B$20),""),IFERROR(_xlfn.XLOOKUP(E5,'⚙️ Configuración Costos'!$A$5:$A$6,'⚙️ Configuración Costos'!$B$5:$B$6),"")) -> 239.84262 | P5: =IF(E5="HERRAJE",A5*O5,M5*O5) -> 96.352217 | Q5: =IF(E5="HERRAJE",0,IFERROR(_xlfn.XLOOKUP(E5,'⚙️ Configuración Costos'!$E$5:$E$6,'⚙️ Configuración Costos'!$F$5:$F$6),"")) -> 6 | R5: =N5*Q5 -> 0 | S5: =P5+R5 -> 96.352217 | T5: =IF(K5="","SIN ID MÓDULO",IF(E5="HERRAJE",IF(OR(O5="",O5<=0),"SIN PRECIO HERRAJE","OK"),IF(OR(O5="",O5<=0),"SIN PRECIO MATERIAL",IF(AND(N5>0,OR(Q5="",Q5<=0)),"SIN PRECIO CINTILLA","OK")))) -> OK | U5: =IF(T5="OK","",IF(T5="SIN PRECIO HERRAJE","Capturar precio: "&D5,IF(T5="SIN PRECIO MATERIAL","Configurar material: "&E5,IF(T5="SIN PRECIO CINTILLA","Configurar cintilla: "&E5,IF(T5="SIN ID MÓDULO","Revisar ID del módulo",""))))) | V5: =IF(T5="OK",0,IF(T5="",0,1)) -> 0
A6: 1 | B6: 619 | C6: 320 | D6: Base Alacena | E6: ARAUCO BLANCO | F6: 0 | G6: 1 | H6: 1 | I6: 0 | J6: 0 | K6: ALA-RIN-656832 | L6: BAS-ALA-6532 | M6: =IF(AND(ISNUMBER(B6),ISNUMBER(C6),B6>0,C6>0),A6*(B6*C6/1000000),0) -> 0.19808 | N6: =IF(AND(ISNUMBER(B6),B6>0),A6*(((G6+H6)*B6+(I6+J6)*C6)/1000),0) -> 1.238 | O6: =IF(E6="HERRAJE",IFERROR(_xlfn.XLOOKUP(D6,'⚙️ Configuración Costos'!$A$11:$A$20,'⚙️ Configuración Costos'!$B$11:$B$20),""),IFERROR(_xlfn.XLOOKUP(E6,'⚙️ Configuración Costos'!$A$5:$A$6,'⚙️ Configuración Costos'!$B$5:$B$6),"")) -> 239.84262 | P6: =IF(E6="HERRAJE",A6*O6,M6*O6) -> 47.508027 | Q6: =IF(E6="HERRAJE",0,IFERROR(_xlfn.XLOOKUP(E6,'⚙️ Configuración Costos'!$E$5:$E$6,'⚙️ Configuración Costos'!$F$5:$F$6),"")) -> 6 | R6: =N6*Q6 -> 7.428 | S6: =P6+R6 -> 54.936027 | T6: =IF(K6="","SIN ID MÓDULO",IF(E6="HERRAJE",IF(OR(O6="",O6<=0),"SIN PRECIO HERRAJE","OK"),IF(OR(O6="",O6<=0),"SIN PRECIO MATERIAL",IF(AND(N6>0,OR(Q6="",Q6<=0)),"SIN PRECIO CINTILLA","OK")))) -> OK | U6: =IF(T6="OK","",IF(T6="SIN PRECIO HERRAJE","Capturar precio: "&D6,IF(T6="SIN PRECIO MATERIAL","Configurar material: "&E6,IF(T6="SIN PRECIO CINTILLA","Configurar cintilla: "&E6,IF(T6="SIN ID MÓDULO","Revisar ID del módulo",""))))) | V6: =IF(T6="OK",0,IF(T6="",0,1)) -> 0
A7: 1 | B7: 619 | C7: 320 | D7: Techo Alacena | E7: ARAUCO BLANCO | F7: 0 | G7: 1 | H7: 1 | I7: 0 | J7: 0 | K7: ALA-RIN-656832 | L7: TEC-ALA-6532 | M7: =IF(AND(ISNUMBER(B7),ISNUMBER(C7),B7>0,C7>0),A7*(B7*C7/1000000),0) -> 0.19808 | N7: =IF(AND(ISNUMBER(B7),B7>0),A7*(((G7+H7)*B7+(I7+J7)*C7)/1000),0) -> 1.238 | O7: =IF(E7="HERRAJE",IFERROR(_xlfn.XLOOKUP(D7,'⚙️ Configuración Costos'!$A$11:$A$20,'⚙️ Configuración Costos'!$B$11:$B$20),""),IFERROR(_xlfn.XLOOKUP(E7,'⚙️ Configuración Costos'!$A$5:$A$6,'⚙️ Configuración Costos'!$B$5:$B$6),"")) -> 239.84262 | P7: =IF(E7="HERRAJE",A7*O7,M7*O7) -> 47.508027 | Q7: =IF(E7="HERRAJE",0,IFERROR(_xlfn.XLOOKUP(E7,'⚙️ Configuración Costos'!$E$5:$E$6,'⚙️ Configuración Costos'!$F$5:$F$6),"")) -> 6 | R7: =N7*Q7 -> 7.428 | S7: =P7+R7 -> 54.936027 | T7: =IF(K7="","SIN ID MÓDULO",IF(E7="HERRAJE",IF(OR(O7="",O7<=0),"SIN PRECIO HERRAJE","OK"),IF(OR(O7="",O7<=0),"SIN PRECIO MATERIAL",IF(AND(N7>0,OR(Q7="",Q7<=0)),"SIN PRECIO CINTILLA","OK")))) -> OK | U7: =IF(T7="OK","",IF(T7="SIN PRECIO HERRAJE","Capturar precio: "&D7,IF(T7="SIN PRECIO MATERIAL","Configurar material: "&E7,IF(T7="SIN PRECIO CINTILLA","Configurar cintilla: "&E7,IF(T7="SIN ID MÓDULO","Revisar ID del módulo",""))))) | V7: =IF(T7="OK",0,IF(T7="",0,1)) -> 0
A8: 1 | B8: 649 | C8: 339 | D8: Tapa Ciega | E8: ARAUCO BLANCO | F8: 0 | G8: 0 | H8: 0 | I8: 0 | J8: 0 | K8: ALA-RIN-656832 | L8: TAP-ALA-6534 | M8: =IF(AND(ISNUMBER(B8),ISNUMBER(C8),B8>0,C8>0),A8*(B8*C8/1000000),0) -> 0.220011 | N8: =IF(AND(ISNUMBER(B8),B8>0),A8*(((G8+H8)*B8+(I8+J8)*C8)/1000),0) -> 0 | O8: =IF(E8="HERRAJE",IFERROR(_xlfn.XLOOKUP(D8,'⚙️ Configuración Costos'!$A$11:$A$20,'⚙️ Configuración Costos'!$B$11:$B$20),""),IFERROR(_xlfn.XLOOKUP(E8,'⚙️ Configuración Costos'!$A$5:$A$6,'⚙️ Configuración Costos'!$B$5:$B$6),"")) -> 239.84262 | P8: =IF(E8="HERRAJE",A8*O8,M8*O8) -> 52.768015 | Q8: =IF(E8="HERRAJE",0,IFERROR(_xlfn.XLOOKUP(E8,'⚙️ Configuración Costos'!$E$5:$E$6,'⚙️ Configuración Costos'!$F$5:$F$6),"")) -> 6 | R8: =N8*Q8 -> 0 | S8: =P8+R8 -> 52.768015 | T8: =IF(K8="","SIN ID MÓDULO",IF(E8="HERRAJE",IF(OR(O8="",O8<=0),"SIN PRECIO HERRAJE","OK"),IF(OR(O8="",O8<=0),"SIN PRECIO MATERIAL",IF(AND(N8>0,OR(Q8="",Q8<=0)),"SIN PRECIO CINTILLA","OK")))) -> OK | U8: =IF(T8="OK","",IF(T8="SIN PRECIO HERRAJE","Capturar precio: "&D8,IF(T8="SIN PRECIO MATERIAL","Configurar material: "&E8,IF(T8="SIN PRECIO CINTILLA","Configurar cintilla: "&E8,IF(T8="SIN ID MÓDULO","Revisar ID del módulo",""))))) | V8: =IF(T8="OK",0,IF(T8="",0,1)) -> 0
A9: 1 | B9: 619 | C9: 256 | D9: Entrepano Alacena | E9: ARAUCO BLANCO | F9: 0 | G9: 1 | H9: 0 | I9: 0 | J9: 0 | K9: ALA-RIN-656832 | L9: ENT-ALA-6526 | M9: =IF(AND(ISNUMBER(B9),ISNUMBER(C9),B9>0,C9>0),A9*(B9*C9/1000000),0) -> 0.158464 | N9: =IF(AND(ISNUMBER(B9),B9>0),A9*(((G9+H9)*B9+(I9+J9)*C9)/1000),0) -> 0.619 | O9: =IF(E9="HERRAJE",IFERROR(_xlfn.XLOOKUP(D9,'⚙️ Configuración Costos'!$A$11:$A$20,'⚙️ Configuración Costos'!$B$11:$B$20),""),IFERROR(_xlfn.XLOOKUP(E9,'⚙️ Configuración Costos'!$A$5:$A$6,'⚙️ Configuración Costos'!$B$5:$B$6),"")) -> 239.84262 | P9: =IF(E9="HERRAJE",A9*O9,M9*O9) -> 38.006421 | Q9: =IF(E9="HERRAJE",0,IFERROR(_xlfn.XLOOKUP(E9,'⚙️ Configuración Costos'!$E$5:$E$6,'⚙️ Configuración Costos'!$F$5:$F$6),"")) -> 6 | R9: =N9*Q9 -> 3.714 | S9: =P9+R9 -> 41.720421 | T9: =IF(K9="","SIN ID MÓDULO",IF(E9="HERRAJE",IF(OR(O9="",O9<=0),"SIN PRECIO HERRAJE","OK"),IF(OR(O9="",O9<=0),"SIN PRECIO MATERIAL",IF(AND(N9>0,OR(Q9="",Q9<=0)),"SIN PRECIO CINTILLA","OK")))) -> OK | U9: =IF(T9="OK","",IF(T9="SIN PRECIO HERRAJE","Capturar precio: "&D9,IF(T9="SIN PRECIO MATERIAL","Configurar material: "&E9,IF(T9="SIN PRECIO CINTILLA","Configurar cintilla: "&E9,IF(T9="SIN ID MÓDULO","Revisar ID del módulo",""))))) | V9: =IF(T9="OK",0,IF(T9="",0,1)) -> 0
A10: 1 | B10: 649 | C10: 70 | D10: Refuerzo Bisagra | E10: ARAUCO BLANCO | F10: 0 | G10: 1 | H10: 1 | I10: 0 | J10: 0 | K10: ALA-RIN-656832 | L10: REF-BIS-ALA-657 | M10: =IF(AND(ISNUMBER(B10),ISNUMBER(C10),B10>0,C10>0),A10*(B10*C10/1000000),0) -> 0.04543 | N10: =IF(AND(ISNUMBER(B10),B10>0),A10*(((G10+H10)*B10+(I10+J10)*C10)/1000),0) -> 1.298 | O10: =IF(E10="HERRAJE",IFERROR(_xlfn.XLOOKUP(D10,'⚙️ Configuración Costos'!$A$11:$A$20,'⚙️ Configuración Costos'!$B$11:$B$20),""),IFERROR(_xlfn.XLOOKUP(E10,'⚙️ Configuración Costos'!$A$5:$A$6,'⚙️ Configuración Costos'!$B$5:$B$6),"")) -> 239.84262 | P10: =IF(E10="HERRAJE",A10*O10,M10*O10) -> 10.89605 | Q10: =IF(E10="HERRAJE",0,IFERROR(_xlfn.XLOOKUP(E10,'⚙️ Configuración Costos'!$E$5:$E$6,'⚙️ Configuración Costos'!$F$5:$F$6),"")) -> 6 | R10: =N10*Q10 -> 7.788 | S10: =P10+R10 -> 18.68405 | T10: =IF(K10="","SIN ID MÓDULO",IF(E10="HERRAJE",IF(OR(O10="",O10<=0),"SIN PRECIO HERRAJE","OK"),IF(OR(O10="",O10<=0),"SIN PRECIO MATERIAL",IF(AND(N10>0,OR(Q10="",Q10<=0)),"SIN PRECIO CINTILLA","OK")))) -> OK | U10: =IF(T10="OK","",IF(T10="SIN PRECIO HERRAJE","Capturar precio: "&D10,IF(T10="SIN PRECIO MATERIAL","Configurar material: "&E10,IF(T10="SIN PRECIO CINTILLA","Configurar cintilla: "&E10,IF(T10="SIN ID MÓDULO","Revisar ID del módulo",""))))) | V10: =IF(T10="OK",0,IF(T10="",0,1)) -> 0
A11: 1 | B11: 320 | C11: 50 | D11: Ajuste Inferior | E11: ARAUCO BLANCO | F11: 0 | G11: 0 | H11: 0 | I11: 1 | J11: 1 | K11: ALA-RIN-656832 | L11: AJU-INF-ALA-325 | M11: =IF(AND(ISNUMBER(B11),ISNUMBER(C11),B11>0,C11>0),A11*(B11*C11/1000000),0) -> 0.016 | N11: =IF(AND(ISNUMBER(B11),B11>0),A11*(((G11+H11)*B11+(I11+J11)*C11)/1000),0) -> 0.1 | O11: =IF(E11="HERRAJE",IFERROR(_xlfn.XLOOKUP(D11,'⚙️ Configuración Costos'!$A$11:$A$20,'⚙️ Configuración Costos'!$B$11:$B$20),""),IFERROR(_xlfn.XLOOKUP(E11,'⚙️ Configuración Costos'!$A$5:$A$6,'⚙️ Configuración Costos'!$B$5:$B$6),"")) -> 239.84262 | P11: =IF(E11="HERRAJE",A11*O11,M11*O11) -> 3.837482 | Q11: =IF(E11="HERRAJE",0,IFERROR(_xlfn.XLOOKUP(E11,'⚙️ Configuración Costos'!$E$5:$E$6,'⚙️ Configuración Costos'!$F$5:$F$6),"")) -> 6 | R11: =N11*Q11 -> 0.6 | S11: =P11+R11 -> 4.437482 | T11: =IF(K11="","SIN ID MÓDULO",IF(E11="HERRAJE",IF(OR(O11="",O11<=0),"SIN PRECIO HERRAJE","OK"),IF(OR(O11="",O11<=0),"SIN PRECIO MATERIAL",IF(AND(N11>0,OR(Q11="",Q11<=0)),"SIN PRECIO CINTILLA","OK")))) -> OK | U11: =IF(T11="OK","",IF(T11="SIN PRECIO HERRAJE","Capturar precio: "&D11,IF(T11="SIN PRECIO MATERIAL","Configurar material: "&E11,IF(T11="SIN PRECIO CINTILLA","Configurar cintilla: "&E11,IF(T11="SIN ID MÓDULO","Revisar ID del módulo",""))))) | V11: =IF(T11="OK",0,IF(T11="",0,1)) -> 0
A12: 1 | B12: 320 | C12: 50 | D12: Ajuste superior | E12: ARAUCO BLANCO | F12: 0 | G12: 0 | H12: 0 | I12: 1 | J12: 1 | K12: ALA-RIN-656832 | L12: AJU-SUP-ALA-325 | M12: =IF(AND(ISNUMBER(B12),ISNUMBER(C12),B12>0,C12>0),A12*(B12*C12/1000000),0) -> 0.016 | N12: =IF(AND(ISNUMBER(B12),B12>0),A12*(((G12+H12)*B12+(I12+J12)*C12)/1000),0) -> 0.1 | O12: =IF(E12="HERRAJE",IFERROR(_xlfn.XLOOKUP(D12,'⚙️ Configuración Costos'!$A$11:$A$20,'⚙️ Configuración Costos'!$B$11:$B$20),""),IFERROR(_xlfn.XLOOKUP(E12,'⚙️ Configuración Costos'!$A$5:$A$6,'⚙️ Configuración Costos'!$B$5:$B$6),"")) -> 239.84262 | P12: =IF(E12="HERRAJE",A12*O12,M12*O12) -> 3.837482 | Q12: =IF(E12="HERRAJE",0,IFERROR(_xlfn.XLOOKUP(E12,'⚙️ Configuración Costos'!$E$5:$E$6,'⚙️ Configuración Costos'!$F$5:$F$6),"")) -> 6 | R12: =N12*Q12 -> 0.6 | S12: =P12+R12 -> 4.437482 | T12: =IF(K12="","SIN ID MÓDULO",IF(E12="HERRAJE",IF(OR(O12="",O12<=0),"SIN PRECIO HERRAJE","OK"),IF(OR(O12="",O12<=0),"SIN PRECIO MATERIAL",IF(AND(N12>0,OR(Q12="",Q12<=0)),"SIN PRECIO CINTILLA","OK")))) -> OK | U12: =IF(T12="OK","",IF(T12="SIN PRECIO HERRAJE","Capturar precio: "&D12,IF(T12="SIN PRECIO MATERIAL","Configurar material: "&E12,IF(T12="SIN PRECIO CINTILLA","Configurar cintilla: "&E12,IF(T12="SIN ID MÓDULO","Revisar ID del módulo",""))))) | V12: =IF(T12="OK",0,IF(T12="",0,1)) -> 0
A13: 1 | B13: 677 | C13: 292 | D13: Puerta Alacena | E13: VESTO NOUGAT | F13: 1 | G13: 1 | H13: 1 | I13: 1 | J13: 1 | K13: ALA-RIN-656832 | L13: PUE-ALA-6829 | M13: =IF(AND(ISNUMBER(B13),ISNUMBER(C13),B13>0,C13>0),A13*(B13*C13/1000000),0) -> 0.197684 | N13: =IF(AND(ISNUMBER(B13),B13>0),A13*(((G13+H13)*B13+(I13+J13)*C13)/1000),0) -> 1.938 | O13: =IF(E13="HERRAJE",IFERROR(_xlfn.XLOOKUP(D13,'⚙️ Configuración Costos'!$A$11:$A$20,'⚙️ Configuración Costos'!$B$11:$B$20),""),IFERROR(_xlfn.XLOOKUP(E13,'⚙️ Configuración Costos'!$A$5:$A$6,'⚙️ Configuración Costos'!$B$5:$B$6),"")) -> 332.85246 | P13: =IF(E13="HERRAJE",A13*O13,M13*O13) -> 65.799606 | Q13: =IF(E13="HERRAJE",0,IFERROR(_xlfn.XLOOKUP(E13,'⚙️ Configuración Costos'!$E$5:$E$6,'⚙️ Configuración Costos'!$F$5:$F$6),"")) -> 9.5 | R13: =N13*Q13 -> 18.411 | S13: =P13+R13 -> 84.210606 | T13: =IF(K13="","SIN ID MÓDULO",IF(E13="HERRAJE",IF(OR(O13="",O13<=0),"SIN PRECIO HERRAJE","OK"),IF(OR(O13="",O13<=0),"SIN PRECIO MATERIAL",IF(AND(N13>0,OR(Q13="",Q13<=0)),"SIN PRECIO CINTILLA","OK")))) -> OK | U13: =IF(T13="OK","",IF(T13="SIN PRECIO HERRAJE","Capturar precio: "&D13,IF(T13="SIN PRECIO MATERIAL","Configurar material: "&E13,IF(T13="SIN PRECIO CINTILLA","Configurar cintilla: "&E13,IF(T13="SIN ID MÓDULO","Revisar ID del módulo",""))))) | V13: =IF(T13="OK",0,IF(T13="",0,1)) -> 0
A14: 1 | B14: 677 | C14: 70 | D14: Ajuste 1 Rinconero | E14: VESTO NOUGAT | F14: 1 | G14: 1 | H14: 1 | I14: 1 | J14: 1 | K14: ALA-RIN-656832 | L14: AJU-RIN-ALA-687 | M14: =IF(AND(ISNUMBER(B14),ISNUMBER(C14),B14>0,C14>0),A14*(B14*C14/1000000),0) -> 0.04739 | N14: =IF(AND(ISNUMBER(B14),B14>0),A14*(((G14+H14)*B14+(I14+J14)*C14)/1000),0) -> 1.494 | O14: =IF(E14="HERRAJE",IFERROR(_xlfn.XLOOKUP(D14,'⚙️ Configuración Costos'!$A$11:$A$20,'⚙️ Configuración Costos'!$B$11:$B$20),""),IFERROR(_xlfn.XLOOKUP(E14,'⚙️ Configuración Costos'!$A$5:$A$6,'⚙️ Configuración Costos'!$B$5:$B$6),"")) -> 332.85246 | P14: =IF(E14="HERRAJE",A14*O14,M14*O14) -> 15.773878 | Q14: =IF(E14="HERRAJE",0,IFERROR(_xlfn.XLOOKUP(E14,'⚙️ Configuración Costos'!$E$5:$E$6,'⚙️ Configuración Costos'!$F$5:$F$6),"")) -> 9.5 | R14: =N14*Q14 -> 14.193 | S14: =P14+R14 -> 29.966878 | T14: =IF(K14="","SIN ID MÓDULO",IF(E14="HERRAJE",IF(OR(O14="",O14<=0),"SIN PRECIO HERRAJE","OK"),IF(OR(O14="",O14<=0),"SIN PRECIO MATERIAL",IF(AND(N14>0,OR(Q14="",Q14<=0)),"SIN PRECIO CINTILLA","OK")))) -> OK | U14: =IF(T14="OK","",IF(T14="SIN PRECIO HERRAJE","Capturar precio: "&D14,IF(T14="SIN PRECIO MATERIAL","Configurar material: "&E14,IF(T14="SIN PRECIO CINTILLA","Configurar cintilla: "&E14,IF(T14="SIN ID MÓDULO","Revisar ID del módulo",""))))) | V14: =IF(T14="OK",0,IF(T14="",0,1)) -> 0
... A19: 30 | B19: 0 | C19: 0 | D19: Tornillo 4x50 mm | E19: HERRAJE | F19: 0 | G19: 0 | H19: 0 | I19: 0 | J19: 0 | K19: ALA-RIN-656832 | L19: TOR-4X50 | M19: =IF(AND(ISNUMBER(B19),ISNUMBER(C19),B19>0,C19>0),A19*(B19*C19/1000000),0) -> 0 | N19: =IF(AND(ISNUMBER(B19),B19>0),A19*(((G19+H19)*B19+(I19+J19)*C19)/1000),0) -> 0 | O19: =IF(E19="HERRAJE",IFERROR(_xlfn.XLOOKUP(D19,'⚙️ Configuración Costos'!$A$11:$A$20,'⚙️ Configuración Costos'!$B$11:$B$20),""),IFERROR(_xlfn.XLOOKUP(E19,'⚙️ Configuración Costos'!$A$5:$A$6,'⚙️ Configuración Costos'!$B$5:$B$6),"")) -> 1.5 | P19: =IF(E19="HERRAJE",A19*O19,M19*O19) -> 45 | Q19: =IF(E19="HERRAJE",0,IFERROR(_xlfn.XLOOKUP(E19,'⚙️ Configuración Costos'!$E$5:$E$6,'⚙️ Configuración Costos'!$F$5:$F$6),"")) -> 0 | R19: =N19*Q19 -> 0 | S19: =P19+R19 -> 45 | T19: =IF(K19="","SIN ID MÓDULO",IF(E19="HERRAJE",IF(OR(O19="",O19<=0),"SIN PRECIO HERRAJE","OK"),IF(OR(O19="",O19<=0),"SIN PRECIO MATERIAL",IF(AND(N19>0,OR(Q19="",Q19<=0)),"SIN PRECIO CINTILLA","OK")))) -> OK | U19: =IF(T19="OK","",IF(T19="SIN PRECIO HERRAJE","Capturar precio: "&D19,IF(T19="SIN PRECIO MATERIAL","Configurar material: "&E19,IF(T19="SIN PRECIO CINTILLA","Configurar cintilla: "&E19,IF(T19="SIN ID MÓDULO","Revisar ID del módulo",""))))) | V19: =IF(T19="OK",0,IF(T19="",0,1)) -> 0
A20: TOTALES | M20: =SUM(M3:M19) -> 1.96792 | N20: =SUM(N3:N19) -> 13.479 | P20: =SUM(P3:P19) -> 605.93377 | R20: =SUM(R3:R19) -> 97.975 | S20: =SUM(S3:S19) -> 703.90877
A21: Alacena 1 Puerta 300 x 680 x 320 mm
A22: 1 | B22: 680 | C22: 320 | D22: Lateral Derecho | E22: ARAUCO BLANCO | F22: 0 | G22: 1 | H22: 1 | I22: 1 | J22: 1 | K22: ALA-1PU-306832 | L22: LAT-ALA-6832-D | M22: =IF(AND(ISNUMBER(B22),ISNUMBER(C22),B22>0,C22>0),A22*(B22*C22/1000000),0) -> 0.2176 | N22: =IF(AND(ISNUMBER(B22),B22>0),A22*(((G22+H22)*B22+(I22+J22)*C22)/1000),0) -> 2 | O22: =IF(E22="HERRAJE",IFERROR(_xlfn.XLOOKUP(D22,'⚙️ Configuración Costos'!$A$11:$A$20,'⚙️ Configuración Costos'!$B$11:$B$20),""),IFERROR(_xlfn.XLOOKUP(E22,'⚙️ Configuración Costos'!$A$5:$A$6,'⚙️ Configuración Costos'!$B$5:$B$6),"")) -> 239.84262 | P22: =IF(E22="HERRAJE",A22*O22,M22*O22) -> 52.189755 | Q22: =IF(E22="HERRAJE",0,IFERROR(_xlfn.XLOOKUP(E22,'⚙️ Configuración Costos'!$E$5:$E$6,'⚙️ Configuración Costos'!$F$5:$F$6),"")) -> 6 | R22: =N22*Q22 -> 12 | S22: =P22+R22 -> 64.189755 | T22: =IF(K22="","SIN ID MÓDULO",IF(E22="HERRAJE",IF(OR(O22="",O22<=0),"SIN PRECIO HERRAJE","OK"),IF(OR(O22="",O22<=0),"SIN PRECIO MATERIAL",IF(AND(N22>0,OR(Q22="",Q22<=0)),"SIN PRECIO CINTILLA","OK")))) -> OK | U22: =IF(T22="OK","",IF(T22="SIN PRECIO HERRAJE","Capturar precio: "&D22,IF(T22="SIN PRECIO MATERIAL","Configurar material: "&E22,IF(T22="SIN PRECIO CINTILLA","Configurar cintilla: "&E22,IF(T22="SIN ID MÓDULO","Revisar ID del módulo",""))))) | V22: =IF(T22="OK",0,IF(T22="",0,1)) -> 0
A23: 1 | B23: 680 | C23: 320 | D23: Lateral Izquierdo | E23: ARAUCO BLANCO | F23: 0 | G23: 1 | H23: 1 | I23: 1 | J23: 1 | K23: ALA-1PU-306832 | L23: LAT-ALA-6832-I | M23: =IF(AND(ISNUMBER(B23),ISNUMBER(C23),B23>0,C23>0),A23*(B23*C23/1000000),0) -> 0.2176 | N23: =IF(AND(ISNUMBER(B23),B23>0),A23*(((G23+H23)*B23+(I23+J23)*C23)/1000),0) -> 2 | O23: =IF(E23="HERRAJE",IFERROR(_xlfn.XLOOKUP(D23,'⚙️ Configuración Costos'!$A$11:$A$20,'⚙️ Configuración Costos'!$B$11:$B$20),""),IFERROR(_xlfn.XLOOKUP(E23,'⚙️ Configuración Costos'!$A$5:$A$6,'⚙️ Configuración Costos'!$B$5:$B$6),"")) -> 239.84262 | P23: =IF(E23="HERRAJE",A23*O23,M23*O23) -> 52.189755 | Q23: =IF(E23="HERRAJE",0,IFERROR(_xlfn.XLOOKUP(E23,'⚙️ Configuración Costos'!$E$5:$E$6,'⚙️ Configuración Costos'!$F$5:$F$6),"")) -> 6 | R23: =N23*Q23 -> 12 | S23: =P23+R23 -> 64.189755 | T23: =IF(K23="","SIN ID MÓDULO",IF(E23="HERRAJE",IF(OR(O23="",O23<=0),"SIN PRECIO HERRAJE","OK"),IF(OR(O23="",O23<=0),"SIN PRECIO MATERIAL",IF(AND(N23>0,OR(Q23="",Q23<=0)),"SIN PRECIO CINTILLA","OK")))) -> OK | U23: =IF(T23="OK","",IF(T23="SIN PRECIO HERRAJE","Capturar precio: "&D23,IF(T23="SIN PRECIO MATERIAL","Configurar material: "&E23,IF(T23="SIN PRECIO CINTILLA","Configurar cintilla: "&E23,IF(T23="SIN ID MÓDULO","Revisar ID del módulo",""))))) | V23: =IF(T23="OK",0,IF(T23="",0,1)) -> 0
A24: 1 | B24: 649 | C24: 269 | D24: Respaldo Alacena | E24: ARAUCO BLANCO | F24: 0 | G24: 0 | H24: 0 | I24: 0 | J24: 0 | K24: ALA-1PU-306832 | L24: RES-ALA-6830 | M24: =IF(AND(ISNUMBER(B24),ISNUMBER(C24),B24>0,C24>0),A24*(B24*C24/1000000),0) -> 0.174581 | N24: =IF(AND(ISNUMBER(B24),B24>0),A24*(((G24+H24)*B24+(I24+J24)*C24)/1000),0) -> 0 | O24: =IF(E24="HERRAJE",IFERROR(_xlfn.XLOOKUP(D24,'⚙️ Configuración Costos'!$A$11:$A$20,'⚙️ Configuración Costos'!$B$11:$B$20),""),IFERROR(_xlfn.XLOOKUP(E24,'⚙️ Configuración Costos'!$A$5:$A$6,'⚙️ Configuración Costos'!$B$5:$B$6),"")) -> 239.84262 | P24: =IF(E24="HERRAJE",A24*O24,M24*O24) -> 41.871965 | Q24: =IF(E24="HERRAJE",0,IFERROR(_xlfn.XLOOKUP(E24,'⚙️ Configuración Costos'!$E$5:$E$6,'⚙️ Configuración Costos'!$F$5:$F$6),"")) -> 6 | R24: =N24*Q24 -> 0 | S24: =P24+R24 -> 41.871965 | T24: =IF(K24="","SIN ID MÓDULO",IF(E24="HERRAJE",IF(OR(O24="",O24<=0),"SIN PRECIO HERRAJE","OK"),IF(OR(O24="",O24<=0),"SIN PRECIO MATERIAL",IF(AND(N24>0,OR(Q24="",Q24<=0)),"SIN PRECIO CINTILLA","OK")))) -> OK | U24: =IF(T24="OK","",IF(T24="SIN PRECIO HERRAJE","Capturar precio: "&D24,IF(T24="SIN PRECIO MATERIAL","Configurar material: "&E24,IF(T24="SIN PRECIO CINTILLA","Configurar cintilla: "&E24,IF(T24="SIN ID MÓDULO","Revisar ID del módulo",""))))) | V24: =IF(T24="OK",0,IF(T24="",0,1)) -> 0
A25: 1 | B25: 269 | C25: 320 | D25: Base Alacena | E25: ARAUCO BLANCO | F25: 0 | G25: 0 | H25: 0 | I25: 1 | J25: 1 | K25: ALA-1PU-306832 | L25: BAS-ALA-3027 | M25: =IF(AND(ISNUMBER(B25),ISNUMBER(C25),B25>0,C25>0),A25*(B25*C25/1000000),0) -> 0.08608 | N25: =IF(AND(ISNUMBER(B25),B25>0),A25*(((G25+H25)*B25+(I25+J25)*C25)/1000),0) -> 0.64 | O25: =IF(E25="HERRAJE",IFERROR(_xlfn.XLOOKUP(D25,'⚙️ Configuración Costos'!$A$11:$A$20,'⚙️ Configuración Costos'!$B$11:$B$20),""),IFERROR(_xlfn.XLOOKUP(E25,'⚙️ Configuración Costos'!$A$5:$A$6,'⚙️ Configuración Costos'!$B$5:$B$6),"")) -> 239.84262 | P25: =IF(E25="HERRAJE",A25*O25,M25*O25) -> 20.645653 | Q25: =IF(E25="HERRAJE",0,IFERROR(_xlfn.XLOOKUP(E25,'⚙️ Configuración Costos'!$E$5:$E$6,'⚙️ Configuración Costos'!$F$5:$F$6),"")) -> 6 | R25: =N25*Q25 -> 3.84 | S25: =P25+R25 -> 24.485653 | T25: =IF(K25="","SIN ID MÓDULO",IF(E25="HERRAJE",IF(OR(O25="",O25<=0),"SIN PRECIO HERRAJE","OK"),IF(OR(O25="",O25<=0),"SIN PRECIO MATERIAL",IF(AND(N25>0,OR(Q25="",Q25<=0)),"SIN PRECIO CINTILLA","OK")))) -> OK | U25: =IF(T25="OK","",IF(T25="SIN PRECIO HERRAJE","Capturar precio: "&D25,IF(T25="SIN PRECIO MATERIAL","Configurar material: "&E25,IF(T25="SIN PRECIO CINTILLA","Configurar cintilla: "&E25,IF(T25="SIN ID MÓDULO","Revisar ID del módulo",""))))) | V25: =IF(T25="OK",0,IF(T25="",0,1)) -> 0
A26: 1 | B26: 269 | C26: 320 | D26: Techo Alacena | E26: ARAUCO BLANCO | F26: 0 | G26: 0 | H26: 0 | I26: 1 | J26: 1 | K26: ALA-1PU-306832 | L26: TEC-ALA-3027 | M26: =IF(AND(ISNUMBER(B26),ISNUMBER(C26),B26>0,C26>0),A26*(B26*C26/1000000),0) -> 0.08608 | N26: =IF(AND(ISNUMBER(B26),B26>0),A26*(((G26+H26)*B26+(I26+J26)*C26)/1000),0) -> 0.64 | O26: =IF(E26="HERRAJE",IFERROR(_xlfn.XLOOKUP(D26,'⚙️ Configuración Costos'!$A$11:$A$20,'⚙️ Configuración Costos'!$B$11:$B$20),""),IFERROR(_xlfn.XLOOKUP(E26,'⚙️ Configuración Costos'!$A$5:$A$6,'⚙️ Configuración Costos'!$B$5:$B$6),"")) -> 239.84262 | P26: =IF(E26="HERRAJE",A26*O26,M26*O26) -> 20.645653 | Q26: =IF(E26="HERRAJE",0,IFERROR(_xlfn.XLOOKUP(E26,'⚙️ Configuración Costos'!$E$5:$E$6,'⚙️ Configuración Costos'!$F$5:$F$6),"")) -> 6 | R26: =N26*Q26 -> 3.84 | S26: =P26+R26 -> 24.485653 | T26: =IF(K26="","SIN ID MÓDULO",IF(E26="HERRAJE",IF(OR(O26="",O26<=0),"SIN PRECIO HERRAJE","OK"),IF(OR(O26="",O26<=0),"SIN PRECIO MATERIAL",IF(AND(N26>0,OR(Q26="",Q26<=0)),"SIN PRECIO CINTILLA","OK")))) -> OK | U26: =IF(T26="OK","",IF(T26="SIN PRECIO HERRAJE","Capturar precio: "&D26,IF(T26="SIN PRECIO MATERIAL","Configurar material: "&E26,IF(T26="SIN PRECIO CINTILLA","Configurar cintilla: "&E26,IF(T26="SIN ID MÓDULO","Revisar ID del módulo",""))))) | V26: =IF(T26="OK",0,IF(T26="",0,1)) -> 0
A27: 1 | B27: 269 | C27: 256 | D27: Entrepano Alacena | E27: ARAUCO BLANCO | F27: 0 | G27: 1 | H27: 1 | I27: 0 | J27: 0 | K27: ALA-1PU-306832 | L27: ENT-ALA-3026 | M27: =IF(AND(ISNUMBER(B27),ISNUMBER(C27),B27>0,C27>0),A27*(B27*C27/1000000),0) -> 0.068864 | N27: =IF(AND(ISNUMBER(B27),B27>0),A27*(((G27+H27)*B27+(I27+J27)*C27)/1000),0) -> 0.538 | O27: =IF(E27="HERRAJE",IFERROR(_xlfn.XLOOKUP(D27,'⚙️ Configuración Costos'!$A$11:$A$20,'⚙️ Configuración Costos'!$B$11:$B$20),""),IFERROR(_xlfn.XLOOKUP(E27,'⚙️ Configuración Costos'!$A$5:$A$6,'⚙️ Configuración Costos'!$B$5:$B$6),"")) -> 239.84262 | P27: =IF(E27="HERRAJE",A27*O27,M27*O27) -> 16.516522 | Q27: =IF(E27="HERRAJE",0,IFERROR(_xlfn.XLOOKUP(E27,'⚙️ Configuración Costos'!$E$5:$E$6,'⚙️ Configuración Costos'!$F$5:$F$6),"")) -> 6 | R27: =N27*Q27 -> 3.228 | S27: =P27+R27 -> 19.744522 | T27: =IF(K27="","SIN ID MÓDULO",IF(E27="HERRAJE",IF(OR(O27="",O27<=0),"SIN PRECIO HERRAJE","OK"),IF(OR(O27="",O27<=0),"SIN PRECIO MATERIAL",IF(AND(N27>0,OR(Q27="",Q27<=0)),"SIN PRECIO CINTILLA","OK")))) -> OK | U27: =IF(T27="OK","",IF(T27="SIN PRECIO HERRAJE","Capturar precio: "&D27,IF(T27="SIN PRECIO MATERIAL","Configurar material: "&E27,IF(T27="SIN PRECIO CINTILLA","Configurar cintilla: "&E27,IF(T27="SIN ID MÓDULO","Revisar ID del módulo",""))))) | V27: =IF(T27="OK",0,IF(T27="",0,1)) -> 0
A28: 1 | B28: 677 | C28: 297 | D28: Puerta Alacena | E28: VESTO NOUGAT | F28: 1 | G28: 1 | H28: 1 | I28: 1 | J28: 1 | K28: ALA-1PU-306832 | L28: PUE-ALA-6830 | M28: =IF(AND(ISNUMBER(B28),ISNUMBER(C28),B28>0,C28>0),A28*(B28*C28/1000000),0) -> 0.201069 | N28: =IF(AND(ISNUMBER(B28),B28>0),A28*(((G28+H28)*B28+(I28+J28)*C28)/1000),0) -> 1.948 | O28: =IF(E28="HERRAJE",IFERROR(_xlfn.XLOOKUP(D28,'⚙️ Configuración Costos'!$A$11:$A$20,'⚙️ Configuración Costos'!$B$11:$B$20),""),IFERROR(_xlfn.XLOOKUP(E28,'⚙️ Configuración Costos'!$A$5:$A$6,'⚙️ Configuración Costos'!$B$5:$B$6),"")) -> 332.85246 | P28: =IF(E28="HERRAJE",A28*O28,M28*O28) -> 66.926311 | Q28: =IF(E28="HERRAJE",0,IFERROR(_xlfn.XLOOKUP(E28,'⚙️ Configuración Costos'!$E$5:$E$6,'⚙️ Configuración Costos'!$F$5:$F$6),"")) -> 9.5 | R28: =N28*Q28 -> 18.506 | S28: =P28+R28 -> 85.432311 | T28: =IF(K28="","SIN ID MÓDULO",IF(E28="HERRAJE",IF(OR(O28="",O28<=0),"SIN PRECIO HERRAJE","OK"),IF(OR(O28="",O28<=0),"SIN PRECIO MATERIAL",IF(AND(N28>0,OR(Q28="",Q28<=0)),"SIN PRECIO CINTILLA","OK")))) -> OK | U28: =IF(T28="OK","",IF(T28="SIN PRECIO HERRAJE","Capturar precio: "&D28,IF(T28="SIN PRECIO MATERIAL","Configurar material: "&E28,IF(T28="SIN PRECIO CINTILLA","Configurar cintilla: "&E28,IF(T28="SIN ID MÓDULO","Revisar ID del módulo",""))))) | V28: =IF(T28="OK",0,IF(T28="",0,1)) -> 0
